Workbook
Name NativeTimeline_Date__Pacific: #N/A

Sheet Late Night Analysis
A1: Hour (Pacific) | B1: Has Reason | C1: Blank Reason | D1: % Blank
A2: 1 AM | B2: =COUNTIFS('Search Audit'!I:I,1,'Search Audit'!E:E,"<>") -> 7 | C2: =COUNTIFS('Search Audit'!I:I,1,'Search Audit'!E:E,"") -> 29 | D2: =IF((B2+C2)=0,0,C2/(B2+C2)) -> 0.80555556
A3: 1 PM | B3: =COUNTIFS('Search Audit'!I:I,13,'Search Audit'!E:E,"<>") -> 4 | C3: =COUNTIFS('Search Audit'!I:I,13,'Search Audit'!E:E,"") -> 23 | D3: =IF((B3+C3)=0,0,C3/(B3+C3)) -> 0.85185185
A4: 10 AM | B4: =COUNTIFS('Search Audit'!I:I,10,'Search Audit'!E:E,"<>") -> 2 | C4: =COUNTIFS('Search Audit'!I:I,10,'Search Audit'!E:E,"") -> 22 | D4: =IF((B4+C4)=0,0,C4/(B4+C4)) -> 0.91666667
A5: 10 PM | B5: =COUNTIFS('Search Audit'!I:I,22,'Search Audit'!E:E,"<>") -> 2 | C5: =COUNTIFS('Search Audit'!I:I,22,'Search Audit'!E:E,"") -> 1 | D5: =IF((B5+C5)=0,0,C5/(B5+C5)) -> 0.33333333
A6: 11 AM | B6: =COUNTIFS('Search Audit'!I:I,11,'Search Audit'!E:E,"<>") -> 3 | C6: =COUNTIFS('Search Audit'!I:I,11,'Search Audit'!E:E,"") -> 17 | D6: =IF((B6+C6)=0,0,C6/(B6+C6)) -> 0.85
A7: 11 PM | B7: =COUNTIFS('Search Audit'!I:I,23,'Search Audit'!E:E,"<>") -> 4 | C7: =COUNTIFS('Search Audit'!I:I,23,'Search Audit'!E:E,"") -> 17 | D7: =IF((B7+C7)=0,0,C7/(B7+C7)) -> 0.80952381
A8: 12 AM | B8: =COUNTIFS('Search Audit'!I:I,0,'Search Audit'!E:E,"<>") -> 12 | C8: =COUNTIFS('Search Audit'!I:I,0,'Search Audit'!E:E,"") -> 27 | D8: =IF((B8+C8)=0,0,C8/(B8+C8)) -> 0.69230769
A9: 12 PM | B9: =COUNTIFS('Search Audit'!I:I,12,'Search Audit'!E:E,"<>") -> 5 | C9: =COUNTIFS('Search Audit'!I:I,12,'Search Audit'!E:E,"") -> 16 | D9: =IF((B9+C9)=0,0,C9/(B9+C9)) -> 0.76190476
A10: 2 AM | B10: =COUNTIFS('Search Audit'!I:I,2,'Search Audit'!E:E,"<>") -> 4 | C10: =COUNTIFS('Search Audit'!I:I,2,'Search Audit'!E:E,"") -> 24 | D10: =IF((B10+C10)=0,0,C10/(B10+C10)) -> 0.85714286
A11: 2 PM | B11: =COUNTIFS('Search Audit'!I:I,14,'Search Audit'!E:E,"<>") -> 3 | C11: =COUNTIFS('Search Audit'!I:I,14,'Search Audit'!E:E,"") -> 24 | D11: =IF((B11+C11)=0,0,C11/(B11+C11)) -> 0.88888889
A12: 3 AM | B12: =COUNTIFS('Search Audit'!I:I,3,'Search Audit'!E:E,"<>") -> 10 | C12: =COUNTIFS('Search Audit'!I:I,3,'Search Audit'!E:E,"") -> 25 | D12: =IF((B12+C12)=0,0,C12/(B12+C12)) -> 0.71428571
A13: 3 PM | B13: =COUNTIFS('Search Audit'!I:I,15,'Search Audit'!E:E,"<>") -> 2 | C13: =COUNTIFS('Search Audit'!I:I,15,'Search Audit'!E:E,"") -> 11 | D13: =IF((B13+C13)=0,0,C13/(B13+C13)) -> 0.84615385
A14: 4 AM | B14: =COUNTIFS('Search Audit'!I:I,4,'Search Audit'!E:E,"<>") -> 7 | C14: =COUNTIFS('Search Audit'!I:I,4,'Search Audit'!E:E,"") -> 23 | D14: =IF((B14+C14)=0,0,C14/(B14+C14)) -> 0.76666667
A15: 4 PM | B15: =COUNTIFS('Search Audit'!I:I,16,'Search Audit'!E:E,"<>") -> 2 | C15: =COUNTIFS('Search Audit'!I:I,16,'Search Audit'!E:E,"") -> 16 | D15: =IF((B15+C15)=0,0,C15/(B15+C15)) -> 0.88888889
A16: 5 AM | B16: =COUNTIFS('Search Audit'!I:I,5,'Search Audit'!E:E,"<>") -> 5 | C16: =COUNTIFS('Search Audit'!I:I,5,'Search Audit'!E:E,"") -> 23 | D16: =IF((B16+C16)=0,0,C16/(B16+C16)) -> 0.82142857
A17: 5 PM | B17: =COUNTIFS('Search Audit'!I:I,17,'Search Audit'!E:E,"<>") -> 0 | C17: =COUNTIFS('Search Audit'!I:I,17,'Search Audit'!E:E,"") -> 5 | D17: =IF((B17+C17)=0,0,C17/(B17+C17)) -> 1
A18: 6 AM | B18: =COUNTIFS('Search Audit'!I:I,6,'Search Audit'!E:E,"<>") -> 12 | C18: =COUNTIFS('Search Audit'!I:I,6,'Search Audit'!E:E,"") -> 27 | D18: =IF((B18+C18)=0,0,C18/(B18+C18)) -> 0.69230769
A19: 6 PM | B19: =COUNTIFS('Search Audit'!I:I,18,'Search Audit'!E:E,"<>") -> 1 | C19: =COUNTIFS('Search Audit'!I:I,18,'Search Audit'!E:E,"") -> 6 | D19: =IF((B19+C19)=0,0,C19/(B19+C19)) -> 0.85714286
A20: 7 AM | B20: =COUNTIFS('Search Audit'!I:I,7,'Search Audit'!E:E,"<>") -> 7 | C20: =COUNTIFS('Search Audit'!I:I,7,'Search Audit'!E:E,"") -> 43 | D20: =IF((B20+C20)=0,0,C20/(B20+C20)) -> 0.86
A21: 7 PM | B21: =COUNTIFS('Search Audit'!I:I,19,'Search Audit'!E:E,"<>") -> 1 | C21: =COUNTIFS('Search Audit'!I:I,19,'Search Audit'!E:E,"") -> 3 | D21: =IF((B21+C21)=0,0,C21/(B21+C21)) -> 0.75
A22: 8 AM | B22: =COUNTIFS('Search Audit'!I:I,8,'Search Audit'!E:E,"<>") -> 15 | C22: =COUNTIFS('Search Audit'!I:I,8,'Search Audit'!E:E,"") -> 37 | D22: =IF((B22+C22)=0,0,C22/(B22+C22)) -> 0.71153846
A23: 8 PM | B23: =COUNTIFS('Search Audit'!I:I,20,'Search Audit'!E:E,"<>") -> 0 | C23: =COUNTIFS('Search Audit'!I:I,20,'Search Audit'!E:E,"") -> 4 | D23: =IF((B23+C23)=0,0,C23/(B23+C23)) -> 1
A24: 9 AM | B24: =COUNTIFS('Search Audit'!I:I,9,'Search Audit'!E:E,"<>") -> 1 | C24: =COUNTIFS('Search Audit'!I:I,9,'Search Audit'!E:E,"") -> 20 | D24: =IF((B24+C24)=0,0,C24/(B24+C24)) -> 0.95238095
A25: 9 PM | B25: =COUNTIFS('Search Audit'!I:I,21,'Search Audit'!E:E,"<>") -> 1 | C25: =COUNTIFS('Search Audit'!I:I,21,'Search Audit'!E:E,"") -> 3 | D25: =IF((B25+C25)=0,0,C25/(B25+C25)) -> 0.75
A28: Grand Total | B28: =SUM(B2:C25) -> 556

Sheet Reason Graph
A3: Row Labels | B3: Count of Search ID
A4: drug investigation | B4: 1
A5: stolen veh | B5: 4
A6: suspect | B6: 8
A7: Suspect Veh | B7: 1
A8: suspect vehicle | B8: 2
A9: wanted subject | B9: 3
A10: (blank) | B10: 446
A11: investigation | B11: 21
A12: Invest | B12: 18
A13: Suspect Vehicle search | B13: 1
A14: case | B14: 11
A15: Investigate | B15: 6
... A33: collision | B33: 1

Sheet Searches by Hour
A1: Hour (Pacific) | B1: Total Searches
A2: 0 | B2: =COUNTIF('Search Audit'!I:I,0) -> 39
A3: 1 | B3: =COUNTIF('Search Audit'!I:I,1) -> 36
A4: 2 | B4: =COUNTIF('Search Audit'!I:I,2) -> 28
A5: 3 | B5: =COUNTIF('Search Audit'!I:I,3) -> 35
A6: 4 | B6: =COUNTIF('Search Audit'!I:I,4) -> 30
A7: 5 | B7: =COUNTIF('Search Audit'!I:I,5) -> 28
A8: 6 | B8: =COUNTIF('Search Audit'!I:I,6) -> 39
A9: 7 | B9: =COUNTIF('Search Audit'!I:I,7) -> 50
A10: 8 | B10: =COUNTIF('Search Audit'!I:I,8) -> 52
A11: 9 | B11: =COUNTIF('Search Audit'!I:I,9) -> 21
A12: 10 | B12: =COUNTIF('Search Audit'!I:I,10) -> 24
A13: 11 | B13: =COUNTIF('Search Audit'!I:I,11) -> 20
A14: 12 | B14: =COUNTIF('Search Audit'!I:I,12) -> 21
A15: 13 | B15: =COUNTIF('Search Audit'!I:I,13) -> 27
A16: 14 | B16: =COUNTIF('Search Audit'!I:I,14) -> 27
A17: 15 | B17: =COUNTIF('Search Audit'!I:I,15) -> 13
A18: 16 | B18: =COUNTIF('Search Audit'!I:I,16) -> 18
A19: 17 | B19: =COUNTIF('Search Audit'!I:I,17) -> 5
A20: 18 | B20: =COUNTIF('Search Audit'!I:I,18) -> 7
A21: 19 | B21: =COUNTIF('Search Audit'!I:I,19) -> 4
A22: 20 | B22: =COUNTIF('Search Audit'!I:I,20) -> 4
A23: 21 | B23: =COUNTIF('Search Audit'!I:I,21) -> 4
A24: 22 | B24: =COUNTIF('Search Audit'!I:I,22) -> 3
A25: 23 | B25: =COUNTIF('Search Audit'!I:I,23) -> 21
A28: GRAND TOTAL | B28: =SUM(B2:B25) -> 556

Sheet Network Analysis
A1: Network Count Analysis
A3: Network Count | B3: Total Searches | C3: Blank Reason | D3: Has Reason | E3: % Blank | F3: Top Reason (Non-Blank) | G3: Top Reason Count
A4: 2 | B4: =COUNTIF('Search Audit'!D:D,A4) -> 1 | C4: =COUNTIFS('Search Audit'!D:D,A4,'Search Audit'!E:E,"") -> 1 | D4: =B4-C4 -> 0 | E4: =IF(B4=0,0,C4/B4) -> 1 | F4: suspect vehicle | G4: 8
A5: 3 | B5: =COUNTIF('Search Audit'!D:D,A5) -> 290 | C5: =COUNTIFS('Search Audit'!D:D,A5,'Search Audit'!E:E,"") -> 226 | D5: =B5-C5 -> 64 | E5: =IF(B5=0,0,C5/B5) -> 0.77931034 | F5: suspect vehicle | G5: 15
A6: 36 | B6: =COUNTIF('Search Audit'!D:D,A6) -> 0 | C6: =COUNTIFS('Search Audit'!D:D,A6,'Search Audit'!E:E,"") -> 0 | D6: =B6-C6 -> 0 | E6: =IF(B6=0,0,C6/B6) -> 0 | F6: suspect vehicle | G6: 7
A7: 15 | B7: =COUNTIF('Search Audit'!D:D,A7) -> 0 | C7: =COUNTIFS('Search Audit'!D:D,A7,'Search Audit'!E:E,"") -> 0 | D7: =B7-C7 -> 0 | E7: =IF(B7=0,0,C7/B7) -> 0 | F7: 10851 / Suspect | G7: 11
A8: 531 | B8: =COUNTIF('Search Audit'!D:D,A8) -> 0 | C8: =COUNTIFS('Search Audit'!D:D,A8,'Search Audit'!E:E,"") -> 0 | D8: =B8-C8 -> 0 | E8: =IF(B8=0,0,C8/B8) -> 0 | F8: suspect ID | G8: 6
A9: 1 | B9: =COUNTIF('Search Audit'!D:D,A9) -> 10 | C9: =COUNTIFS('Search Audit'!D:D,A9,'Search Audit'!E:E,"") -> 6 | D9: =B9-C9 -> 4 | E9: =IF(B9=0,0,C9/B9) -> 0.6 | F9: THREATS OF SELF HARM | G9: 6
A10: 433 | B10: =COUNTIF('Search Audit'!D:D,A10) -> 0 | C10: =COUNTIFS('Search Audit'!D:D,A10,'Search Audit'!E:E,"") -> 0 | D10: =B10-C10 -> 0 | E10: =IF(B10=0,0,C10/B10) -> 0 | F10: Drug Investigation | G10: 17
A11: 532 | B11: =COUNTIF('Search Audit'!D:D,A11) -> 0 | C11: =COUNTIFS('Search Audit'!D:D,A11,'Search Audit'!E:E,"") -> 0 | D11: =B11-C11 -> 0 | E11: =IF(B11=0,0,C11/B11) -> 0 | F11: Drug Investigation | G11: 7
A12: 432 | B12: =COUNTIF('Search Audit'!D:D,A12) -> 0 | C12: =COUNTIFS('Search Audit'!D:D,A12,'Search Audit'!E:E,"") -> 0 | D12: =B12-C12 -> 0 | E12: =IF(B12=0,0,C12/B12) -> 0 | F12: suspect ID | G12: 21
A13: 35 | B13: =COUNTIF('Search Audit'!D:D,A13) -> 0 | C13: =COUNTIFS('Search Audit'!D:D,A13,'Search Audit'!E:E,"") -> 0 | D13: =B13-C13 -> 0 | E13: =IF(B13=0,0,C13/B13) -> 0 | F13: Pattern of travel | G13: 4
A14: 575 | B14: =COUNTIF('Search Audit'!D:D,A14) -> 0 | C14: =COUNTIFS('Search Audit'!D:D,A14,'Search Audit'!E:E,"") -> 0 | D14: =B14-C14 -> 0 | E14: =IF(B14=0,0,C14/B14) -> 0 | F14: ycso suspect | G14: 4
A15: 4 | B15: =COUNTIF('Search Audit'!D:D,A15) -> 0 | C15: =COUNTIFS('Search Audit'!D:D,A15,'Search Audit'!E:E,"") -> 0 | D15: =B15-C15 -> 0 | E15: =IF(B15=0,0,C15/B15) -> 0 | F15: STOLEN VEHICLE | G15: 2
... A34: 826 | B34: =COUNTIF('Search Audit'!D:D,A34) -> 0 | C34: =COUNTIFS('Search Audit'!D:D,A34,'Search Audit'!E:E,"") -> 0 | D34: =B34-C34 -> 0 | E34: =IF(B34=0,0,C34/B34) -> 0 | F34: 487 pc suspect | G34: 1
A35: TOTAL | B35: =SUM(B4:B34) -> 305 | C35: =SUM(C4:C34) -> 237 | D35: =SUM(D4:D34) -> 68 | E35: =IF(B35=0,0,C35/B35) -> 0.77704918
A38: Chart Data: Top 10 Network Counts by Volume
A39: Network Count | B39: Has Reason | C39: Blank Reason
A40: Net: 2 | B40: =D4 -> 0 | C40: =C4 -> 1
A41: Net: 3 | B41: =D5 -> 64 | C41: =C5 -> 226
A42: Net: 36 | B42: =D6 -> 0 | C42: =C6 -> 0
A43: Net: 15 | B43: =D7 -> 0 | C43: =C7 -> 0
A44: Net: 531 | B44: =D8 -> 0 | C44: =C8 -> 0
A45: Net: 1 | B45: =D9 -> 4 | C45: =C9 -> 6
A46: Net: 433 | B46: =D10 -> 0 | C46: =C10 -> 0
A47: Net: 532 | B47: =D11 -> 0 | C47: =C11 -> 0
A48: Net: 432 | B48: =D12 -> 0 | C48: =C12 -> 0
A49: Net: 35 | B49: =D13 -> 0 | C49: =C13 -> 0
A52: % Blank Rate by Network Count
A53: Network Count | B53: % Blank
A54: 2 | B54: =E4 -> 1
A55: 3 | B55: =E5 -> 0.77931034
A56: 36 | B56: =E6 -> 0
A57: 15 | B57: =E7 -> 0
A58: 531 | B58: =E8 -> 0
A59: 1 | B59: =E9 -> 0.6
A60: 433 | B60: =E10 -> 0
A61: 532 | B61: =E11 -> 0
A62: 432 | B62: =E12 -> 0
A63: 35 | B63: =E13 -> 0

Sheet Search Audit
A1: Search ID | B1: User ID | C1: Search Date (UTC/Zulu) | D1: Network Count | E1: Reason | F1: Search Date (Pacific) | G1: Date (Pacific) | H1: Day of Week | I1: Hour (Pacific)
A2: f8f149f8-d49b-47ce-94f7-f71836b1c213 | B2: *** | C2: 46107.717 | D2: 3 | F2: 46107.425 | G2: 46107 | H2: Thursday | I2: 10
A3: 0245d710-0f42-4536-8da4-e89d0b7fca66 | B3: *** | C3: 46107.743 | D3: 202 | F3: 46107.451 | G3: 46107 | H3: Thursday | I3: 10
A4: 450a2436-ffb9-4091-870e-bb577d83e740 | B4: *** | C4: 46107.759 | D4: 3 | F4: 46107.468 | G4: 46107 | H4: Thursday | I4: 11
A5: 1f9a2b8c-06f9-4d82-82c9-88bec1416b8d | B5: *** | C5: 46107.76 | D5: 3 | F5: 46107.468 | G5: 46107 | H5: Thursday | I5: 11
A6: 35c97636-cceb-4c8f-ab05-5fba5fad5db1 | B6: *** | C6: 46107.764 | D6: 202 | F6: 46107.472 | G6: 46107 | H6: Thursday | I6: 11
A7: ec8cd435-9104-4b33-8aff-e4c6efc47069 | B7: *** | C7: 46107.776 | D7: 3 | F7: 46107.485 | G7: 46107 | H7: Thursday | I7: 11
A8: 9deb58ee-6fa6-4945-8f0d-2552ad873694 | B8: *** | C8: 46107.793 | D8: 202 | F8: 46107.501 | G8: 46107 | H8: Thursday | I8: 12
A9: ee8e65e1-754b-414f-923e-893043d18688 | B9: *** | C9: 46107.794 | D9: 3 | F9: 46107.503 | G9: 46107 | H9: Thursday | I9: 12
A10: a8b6e533-f5d8-4d02-bdd8-2c5918e24a5a | B10: *** | C10: 46107.817 | D10: 3 | F10: 46107.526 | G10: 46107 | H10: Thursday | I10: 12
A11: 8b389137-3d8f-4354-a0ba-a86eead912b0 | B11: *** | C11: 46107.835 | D11: 269 | F11: 46107.544 | G11: 46107 | H11: Thursday | I11: 13
A12: fba041cb-c412-4eef-a62b-7004f0327c7d | B12: *** | C12: 46107.836 | D12: 3 | F12: 46107.544 | G12: 46107 | H12: Thursday | I12: 13
A13: 9128dc15-c017-4362-91c9-21df0dd02fa2 | B13: *** | C13: 46107.843 | D13: 202 | F13: 46107.552 | G13: 46107 | H13: Thursday | I13: 13
... A16: 25eb2c00-3ed3-49ce-8cdc-e37b77b598e8 | B16: *** | C16: 46108.078 | D16: 3 | F16: 46107.787 | G16: 46107 | H16: Thursday | I16: 18
A17: 3bf1e235-c174-42c7-b634-9c5f18b60543 | B17: *** | C17: 46108.283 | D17: 3 | E17: investigation | F17: 46107.991 | G17: 46107 | H17: Thursday | I17: 23
A18: 6d25ff15-d390-41da-898e-24079c7cf91a | B18: *** | C18: 46108.622 | D18: 202 | F18: 46108.33 | G18: 46108 | H18: Friday | I18: 7
A19: 4008265e-1227-4500-8cee-09bc72cc6c53 | B19: *** | C19: 46108.631 | D19: 202 | F19: 46108.339 | G19: 46108 | H19: Friday | I19: 8
A20: 91f824ab-c6af-4fc6-ab76-47762aa88fc5 | B20: *** | C20: 46108.674 | D20: 202 | F20: 46108.382 | G20: 46108 | H20: Friday | I20: 9
A21: 76fda84b-49bf-4580-9502-a85c0b1cbf03 | B21: *** | C21: 46108.863 | D21: 202 | F21: 46108.571 | G21: 46108 | H21: Friday | I21: 13
A22: ade7f1cb-9d51-4225-8831-69fb0c86faa0 | B22: *** | C22: 46108.954 | D22: 3 | F22: 46108.663 | G22: 46108 | H22: Friday | I22: 15
A23: 4799764d-8b3f-4681-83bf-d99d83493e3a | B23: *** | C23: 46108.97 | D23: 3 | F23: 46108.679 | G23: 46108 | H23: Friday | I23: 16
A24: 320fdbc6-a537-4528-a163-0ce87a2353c5 | B24: *** | C24: 46109.08 | D24: 3 | F24: 46108.788 | G24: 46108 | H24: Friday | I24: 18
A25: 445b9545-5a1b-4b21-a109-f2d179191d1b | B25: *** | C25: 46109.127 | D25: 269 | F25: 46108.835 | G25: 46108 | H25: Friday | I25: 20
A26: 8ed16535-d59e-41ca-b252-2a281b95d1fa | B26: *** | C26: 46109.789 | D26: 3 | F26: 46109.497 | G26: 46109 | H26: Saturday | I26: 11
A27: 77a90166-da1b-4ead-83b3-167e76428514 | B27: *** | C27: 46109.797 | D27: 3 | F27: 46109.505 | G27: 46109 | H27: Saturday | I27: 12
A28: 97b2e435-1ec6-4c1d-88dd-7319feb92713 | B28: *** | C28: 46109.836 | D28: 3 | F28: 46109.544 | G28: 46109 | H28: Saturday | I28: 13
A29: 82ce7be4-7d43-4177-b0f3-77942999c01d | B29: *** | C29: 46110.131 | D29: 269 | F29: 46109.839 | G29: 46109 | H29: Saturday | I29: 20
... A37: 96919256-16e4-4b36-ad37-46b08c3d4e38 | B37: *** | C37: 46111.537 | D37: 269 | F37: 46111.245 | G37: 46111 | H37: Monday | I37: 5
A38: 0ad81a13-1e4d-4a57-9fbd-fe8c6ff32de7 | B38: *** | C38: 46111.652 | D38: 3 | E38: Invest | F38: 46111.36 | G38: 46111 | H38: Monday | I38: 8
A39: 221da6cc-a2ec-465d-9b7d-52c2a148dd13 | B39: *** | C39: 46111.672 | D39: 202 | F39: 46111.381 | G39: 46111 | H39: Monday | I39: 9
A40: 47dd147f-39fd-451a-9c2b-9f54129de928 | B40: *** | C40: 46111.744 | D40: 3 | F40: 46111.452 | G40: 46111 | H40: Monday | I40: 10
A41: 87cc67f9-2c82-482e-a0fd-a89dce30052b | B41: *** | C41: 46111.886 | D41: 3 | F41: 46111.595 | G41: 46111 | H41: Monday | I41: 14
A42: 8f874dfc-4a79-4027-b6e4-ad50d5a4cada | B42: *** | C42: 46111.906 | D42: 3 | E42: investigation | F42: 46111.614 | G42: 46111 | H42: Monday | I42: 14
A43: b7420707-b04c-4b86-b7cf-7275a22a282b | B43: *** | C43: 46112.239 | D43: 3 | E43: Suspect Vehicle search | F43: 46111.947 | G43: 46111 | H43: Monday | I43: 22
A44: 0ee8c71f-84be-4d48-9343-03972d38a084 | B44: *** | C44: 46112.269 | D44: 3 | F44: 46111.978 | G44: 46111 | H44: Monday | I44: 23
A45: f6fdd320-23cb-4461-bf04-032a9bc1e42a | B45: *** | C45: 46112.344 | D45: 269 | F45: 46112.052 | G45: 46112 | H45: Tuesday | I45: 1
A46: 345a7e9b-ad28-4291-9ed1-eab79d758037 | B46: *** | C46: 46112.347 | D46: 3 | F46: 46112.055 | G46: 46112 | H46: Tuesday | I46: 1
A47: 2e25c5d7-9afe-4a3c-9019-06d1358ffde4 | B47: *** | C47: 46112.453 | D47: 269 | F47: 46112.161 | G47: 46112 | H47: Tuesday | I47: 3
A48: a0ac1203-7a99-44a5-833e-ea0135a27486 | B48: *** | C48: 46112.549 | D48: 269 | E48: investigation | F48: 46112.257 | G48: 46112 | H48: Tuesday | I48: 6
A49: bd0f5b5f-1aad-4a14-af38-7a8f46a6c151 | B49: *** | C49: 46112.551 | D49: 269 | F49: 46112.259 | G49: 46112 | H49: Tuesday | I49: 6
...

Sheet flock_run_log
A1: Run Date/Time | B1: Rows Before | C1: Rows After | D1: New Rows | E1: New Rows Date Min | F1: New Rows Date Max | G1: Blank Reason # | H1: Blank Reason % | I1: Backdated Entries | J1: Backdated Detail | M1: Total Backdated Entries
M2: =SUM(I:I) -> 0
