Workbook
Name NativeTimeline_Date__Pacific: #N/A

Sheet Dashboard
A1: Headline KPIs | K1: Reason Pie Chart
A3: Total Searches | B3: =COUNTA('Search Audit'!A:A)-1 -> 2060
A5: Searches with Reason | B5: =COUNTIF('Search Audit'!E:E,"<>")-1 -> 873
A7: Blank Reason Count | B7: =B3-B5 -> 1187
A9: Blank Reason % | B9: =B7/B3 -> 0.57621359
A11: Late Night Searches (10pm-5am) | B11: {=SUMPRODUCT(('Search Audit'!I2:I1770<=5)+('Search Audit'!I2:I1770>=22))} -> 723
A13: Late Night % of Total | B13: =B11/B3 -> 0.35097087
A15: Late Night Blank % | B15: {=SUMPRODUCT((('Search Audit'!I2:I1770<=5)+('Search Audit'!I2:I1770>=22))*('Search Audit'!E2:E1770=""))/B7} -> 0.36731255
A17: Total Backdated Entries | B17: =flock_run_log!M2 -> 0
A19: Searches by Hour Chart
A45: Blank Reason % by Hour

Sheet Reason Graph
A3: Row Labels | B3: Count of Search ID
A4: 20 | B4: 1
A5: 207 | B5: 6
A6: 242 | B6: 1
A7: 288 | B7: 3
A8: 836 | B8: 1
A9: 1036 | B9: 3
A10: 2800.2 | B10: 1
A11: 5150 | B11: 1
A12: 10851 | B12: 18
A13: 49949 | B13: 2
A14: 10-36 | B14: 2
A15: 166 pc | B15: 1
A16: 207 sus | B16: 3
A17: 21 suspect | B17: 1
A18: 211 SUSPECT | B18: 8
A19: 211 vehicle | B19: 1
A20: 243d suspect | B20: 4
A21: 246 pc | B21: 1
A22: 288 pc | B22: 1
A23: 288 SUSP | B23: 1
A24: 288PC | B24: 1
A25: 314 suspect | B25: 2
... A197: R7-25-0008 | B197: 1

Sheet Late Night Analysis
A1: Hour (Pacific) | B1: Has Reason | C1: Blank Reason | D1: % Blank | R1: Has Reason Total | S1: =SUM(B2:B25) -> 873
A2: 1 AM | B2: =COUNTIFS('Search Audit'!I:I,1,'Search Audit'!E:E,"<>") -> 49 | C2: =COUNTIFS('Search Audit'!I:I,1,'Search Audit'!E:E,"") -> 62 | D2: =IF((B2+C2)=0,0,C2/(B2+C2)) -> 0.55855856
A3: 1 PM | B3: =COUNTIFS('Search Audit'!I:I,13,'Search Audit'!E:E,"<>") -> 38 | C3: =COUNTIFS('Search Audit'!I:I,13,'Search Audit'!E:E,"") -> 46 | D3: =IF((B3+C3)=0,0,C3/(B3+C3)) -> 0.54761905 | R3: Blank Reason Total | S3: =SUM(C2:C25) -> 1187
A4: 10 AM | B4: =COUNTIFS('Search Audit'!I:I,10,'Search Audit'!E:E,"<>") -> 55 | C4: =COUNTIFS('Search Audit'!I:I,10,'Search Audit'!E:E,"") -> 69 | D4: =IF((B4+C4)=0,0,C4/(B4+C4)) -> 0.55645161
A5: 10 PM | B5: =COUNTIFS('Search Audit'!I:I,22,'Search Audit'!E:E,"<>") -> 10 | C5: =COUNTIFS('Search Audit'!I:I,22,'Search Audit'!E:E,"") -> 12 | D5: =IF((B5+C5)=0,0,C5/(B5+C5)) -> 0.54545455 | R5: Avg % Blank Reason | S5: =AVERAGE(D2:D25) -> 0.58873292
A6: 11 AM | B6: =COUNTIFS('Search Audit'!I:I,11,'Search Audit'!E:E,"<>") -> 32 | C6: =COUNTIFS('Search Audit'!I:I,11,'Search Audit'!E:E,"") -> 39 | D6: =IF((B6+C6)=0,0,C6/(B6+C6)) -> 0.54929577
A7: 11 PM | B7: =COUNTIFS('Search Audit'!I:I,23,'Search Audit'!E:E,"<>") -> 7 | C7: =COUNTIFS('Search Audit'!I:I,23,'Search Audit'!E:E,"") -> 31 | D7: =IF((B7+C7)=0,0,C7/(B7+C7)) -> 0.81578947 | R7: Grand Total | S7: =SUM(B2:C25) -> 2060
A8: 12 AM | B8: =COUNTIFS('Search Audit'!I:I,0,'Search Audit'!E:E,"<>") -> 24 | C8: =COUNTIFS('Search Audit'!I:I,0,'Search Audit'!E:E,"") -> 50 | D8: =IF((B8+C8)=0,0,C8/(B8+C8)) -> 0.67567568
A9: 12 PM | B9: =COUNTIFS('Search Audit'!I:I,12,'Search Audit'!E:E,"<>") -> 31 | C9: =COUNTIFS('Search Audit'!I:I,12,'Search Audit'!E:E,"") -> 52 | D9: =IF((B9+C9)=0,0,C9/(B9+C9)) -> 0.62650602
A10: 2 AM | B10: =COUNTIFS('Search Audit'!I:I,2,'Search Audit'!E:E,"<>") -> 61 | C10: =COUNTIFS('Search Audit'!I:I,2,'Search Audit'!E:E,"") -> 71 | D10: =IF((B10+C10)=0,0,C10/(B10+C10)) -> 0.53787879
A11: 2 PM | B11: =COUNTIFS('Search Audit'!I:I,14,'Search Audit'!E:E,"<>") -> 47 | C11: =COUNTIFS('Search Audit'!I:I,14,'Search Audit'!E:E,"") -> 43 | D11: =IF((B11+C11)=0,0,C11/(B11+C11)) -> 0.47777778
A12: 3 AM | B12: =COUNTIFS('Search Audit'!I:I,3,'Search Audit'!E:E,"<>") -> 68 | C12: =COUNTIFS('Search Audit'!I:I,3,'Search Audit'!E:E,"") -> 90 | D12: =IF((B12+C12)=0,0,C12/(B12+C12)) -> 0.56962025
A13: 3 PM | B13: =COUNTIFS('Search Audit'!I:I,15,'Search Audit'!E:E,"<>") -> 35 | C13: =COUNTIFS('Search Audit'!I:I,15,'Search Audit'!E:E,"") -> 38 | D13: =IF((B13+C13)=0,0,C13/(B13+C13)) -> 0.52054795
A14: 4 AM | B14: =COUNTIFS('Search Audit'!I:I,4,'Search Audit'!E:E,"<>") -> 63 | C14: =COUNTIFS('Search Audit'!I:I,4,'Search Audit'!E:E,"") -> 97 | D14: =IF((B14+C14)=0,0,C14/(B14+C14)) -> 0.60625
A15: 4 PM | B15: =COUNTIFS('Search Audit'!I:I,16,'Search Audit'!E:E,"<>") -> 23 | C15: =COUNTIFS('Search Audit'!I:I,16,'Search Audit'!E:E,"") -> 23 | D15: =IF((B15+C15)=0,0,C15/(B15+C15)) -> 0.5
A16: 5 AM | B16: =COUNTIFS('Search Audit'!I:I,5,'Search Audit'!E:E,"<>") -> 44 | C16: =COUNTIFS('Search Audit'!I:I,5,'Search Audit'!E:E,"") -> 75 | D16: =IF((B16+C16)=0,0,C16/(B16+C16)) -> 0.6302521
A17: 5 PM | B17: =COUNTIFS('Search Audit'!I:I,17,'Search Audit'!E:E,"<>") -> 20 | C17: =COUNTIFS('Search Audit'!I:I,17,'Search Audit'!E:E,"") -> 19 | D17: =IF((B17+C17)=0,0,C17/(B17+C17)) -> 0.48717949
A18: 6 AM | B18: =COUNTIFS('Search Audit'!I:I,6,'Search Audit'!E:E,"<>") -> 47 | C18: =COUNTIFS('Search Audit'!I:I,6,'Search Audit'!E:E,"") -> 77 | D18: =IF((B18+C18)=0,0,C18/(B18+C18)) -> 0.62096774
A19: 6 PM | B19: =COUNTIFS('Search Audit'!I:I,18,'Search Audit'!E:E,"<>") -> 13 | C19: =COUNTIFS('Search Audit'!I:I,18,'Search Audit'!E:E,"") -> 20 | D19: =IF((B19+C19)=0,0,C19/(B19+C19)) -> 0.60606061
A20: 7 AM | B20: =COUNTIFS('Search Audit'!I:I,7,'Search Audit'!E:E,"<>") -> 71 | C20: =COUNTIFS('Search Audit'!I:I,7,'Search Audit'!E:E,"") -> 86 | D20: =IF((B20+C20)=0,0,C20/(B20+C20)) -> 0.5477707
A21: 7 PM | B21: =COUNTIFS('Search Audit'!I:I,19,'Search Audit'!E:E,"<>") -> 9 | C21: =COUNTIFS('Search Audit'!I:I,19,'Search Audit'!E:E,"") -> 15 | D21: =IF((B21+C21)=0,0,C21/(B21+C21)) -> 0.625
A22: 8 AM | B22: =COUNTIFS('Search Audit'!I:I,8,'Search Audit'!E:E,"<>") -> 60 | C22: =COUNTIFS('Search Audit'!I:I,8,'Search Audit'!E:E,"") -> 79 | D22: =IF((B22+C22)=0,0,C22/(B22+C22)) -> 0.56834532
A23: 8 PM | B23: =COUNTIFS('Search Audit'!I:I,20,'Search Audit'!E:E,"<>") -> 7 | C23: =COUNTIFS('Search Audit'!I:I,20,'Search Audit'!E:E,"") -> 17 | D23: =IF((B23+C23)=0,0,C23/(B23+C23)) -> 0.70833333
A24: 9 AM | B24: =COUNTIFS('Search Audit'!I:I,9,'Search Audit'!E:E,"<>") -> 54 | C24: =COUNTIFS('Search Audit'!I:I,9,'Search Audit'!E:E,"") -> 64 | D24: =IF((B24+C24)=0,0,C24/(B24+C24)) -> 0.54237288
A25: 9 PM | B25: =COUNTIFS('Search Audit'!I:I,21,'Search Audit'!E:E,"<>") -> 5 | C25: =COUNTIFS('Search Audit'!I:I,21,'Search Audit'!E:E,"") -> 12 | D25: =IF((B25+C25)=0,0,C25/(B25+C25)) -> 0.70588235

Sheet Searches by Hour
A1: Hour (Pacific) | B1: Total Searches
A2: 0 | B2: =COUNTIF('Search Audit'!I:I,0) -> 74
A3: 1 | B3: =COUNTIF('Search Audit'!I:I,1) -> 111
A4: 2 | B4: =COUNTIF('Search Audit'!I:I,2) -> 132
A5: 3 | B5: =COUNTIF('Search Audit'!I:I,3) -> 158
A6: 4 | B6: =COUNTIF('Search Audit'!I:I,4) -> 160
A7: 5 | B7: =COUNTIF('Search Audit'!I:I,5) -> 119
A8: 6 | B8: =COUNTIF('Search Audit'!I:I,6) -> 124
A9: 7 | B9: =COUNTIF('Search Audit'!I:I,7) -> 157
A10: 8 | B10: =COUNTIF('Search Audit'!I:I,8) -> 139
A11: 9 | B11: =COUNTIF('Search Audit'!I:I,9) -> 118
A12: 10 | B12: =COUNTIF('Search Audit'!I:I,10) -> 124
A13: 11 | B13: =COUNTIF('Search Audit'!I:I,11) -> 71
A14: 12 | B14: =COUNTIF('Search Audit'!I:I,12) -> 83
A15: 13 | B15: =COUNTIF('Search Audit'!I:I,13) -> 84
A16: 14 | B16: =COUNTIF('Search Audit'!I:I,14) -> 90
A17: 15 | B17: =COUNTIF('Search Audit'!I:I,15) -> 73
A18: 16 | B18: =COUNTIF('Search Audit'!I:I,16) -> 46
A19: 17 | B19: =COUNTIF('Search Audit'!I:I,17) -> 39
A20: 18 | B20: =COUNTIF('Search Audit'!I:I,18) -> 33
A21: 19 | B21: =COUNTIF('Search Audit'!I:I,19) -> 24
A22: 20 | B22: =COUNTIF('Search Audit'!I:I,20) -> 24
A23: 21 | B23: =COUNTIF('Search Audit'!I:I,21) -> 17
A24: 22 | B24: =COUNTIF('Search Audit'!I:I,22) -> 22
A25: 23 | B25: =COUNTIF('Search Audit'!I:I,23) -> 38
A28: GRAND TOTAL | B28: =SUM(B2:B25) -> 2060

Sheet Network Analysis
A1: Network Count Analysis
A3: Network Count | B3: Total Searches | C3: Blank Reason | D3: Has Reason | E3: % Blank | F3: Top Reason (Non-Blank) | G3: Top Reason Count
A4: 2 | B4: =COUNTIF('Search Audit'!D:D,A4) -> 229 | C4: =COUNTIFS('Search Audit'!D:D,A4,'Search Audit'!E:E,"") -> 142 | D4: =B4-C4 -> 87 | E4: =IF(B4=0,0,C4/B4) -> 0.62008734 | F4: suspect vehicle | G4: 8
A5: 3 | B5: =COUNTIF('Search Audit'!D:D,A5) -> 522 | C5: =COUNTIFS('Search Audit'!D:D,A5,'Search Audit'!E:E,"") -> 280 | D5: =B5-C5 -> 242 | E5: =IF(B5=0,0,C5/B5) -> 0.53639847 | F5: suspect vehicle | G5: 15
A6: 36 | B6: =COUNTIF('Search Audit'!D:D,A6) -> 104 | C6: =COUNTIFS('Search Audit'!D:D,A6,'Search Audit'!E:E,"") -> 89 | D6: =B6-C6 -> 15 | E6: =IF(B6=0,0,C6/B6) -> 0.85576923 | F6: suspect vehicle | G6: 7
A7: 15 | B7: =COUNTIF('Search Audit'!D:D,A7) -> 81 | C7: =COUNTIFS('Search Audit'!D:D,A7,'Search Audit'!E:E,"") -> 44 | D7: =B7-C7 -> 37 | E7: =IF(B7=0,0,C7/B7) -> 0.54320988 | F7: 10851 / Suspect | G7: 11
A8: 531 | B8: =COUNTIF('Search Audit'!D:D,A8) -> 154 | C8: =COUNTIFS('Search Audit'!D:D,A8,'Search Audit'!E:E,"") -> 87 | D8: =B8-C8 -> 67 | E8: =IF(B8=0,0,C8/B8) -> 0.56493506 | F8: suspect ID | G8: 6
A9: 1 | B9: =COUNTIF('Search Audit'!D:D,A9) -> 85 | C9: =COUNTIFS('Search Audit'!D:D,A9,'Search Audit'!E:E,"") -> 50 | D9: =B9-C9 -> 35 | E9: =IF(B9=0,0,C9/B9) -> 0.58823529 | F9: THREATS OF SELF HARM | G9: 6
A10: 433 | B10: =COUNTIF('Search Audit'!D:D,A10) -> 43 | C10: =COUNTIFS('Search Audit'!D:D,A10,'Search Audit'!E:E,"") -> 6 | D10: =B10-C10 -> 37 | E10: =IF(B10=0,0,C10/B10) -> 0.13953488 | F10: Drug Investigation | G10: 17
A11: 532 | B11: =COUNTIF('Search Audit'!D:D,A11) -> 41 | C11: =COUNTIFS('Search Audit'!D:D,A11,'Search Audit'!E:E,"") -> 21 | D11: =B11-C11 -> 20 | E11: =IF(B11=0,0,C11/B11) -> 0.51219512 | F11: Drug Investigation | G11: 7
A12: 432 | B12: =COUNTIF('Search Audit'!D:D,A12) -> 41 | C12: =COUNTIFS('Search Audit'!D:D,A12,'Search Audit'!E:E,"") -> 5 | D12: =B12-C12 -> 36 | E12: =IF(B12=0,0,C12/B12) -> 0.12195122 | F12: suspect ID | G12: 21
A13: 35 | B13: =COUNTIF('Search Audit'!D:D,A13) -> 48 | C13: =COUNTIFS('Search Audit'!D:D,A13,'Search Audit'!E:E,"") -> 37 | D13: =B13-C13 -> 11 | E13: =IF(B13=0,0,C13/B13) -> 0.77083333 | F13: Pattern of travel | G13: 4
A14: 575 | B14: =COUNTIF('Search Audit'!D:D,A14) -> 120 | C14: =COUNTIFS('Search Audit'!D:D,A14,'Search Audit'!E:E,"") -> 70 | D14: =B14-C14 -> 50 | E14: =IF(B14=0,0,C14/B14) -> 0.58333333 | F14: ycso suspect | G14: 4
A15: 4 | B15: =COUNTIF('Search Audit'!D:D,A15) -> 31 | C15: =COUNTIFS('Search Audit'!D:D,A15,'Search Audit'!E:E,"") -> 21 | D15: =B15-C15 -> 10 | E15: =IF(B15=0,0,C15/B15) -> 0.67741935 | F15: STOLEN VEHICLE | G15: 2
... A34: 826 | B34: =COUNTIF('Search Audit'!D:D,A34) -> 1 | C34: =COUNTIFS('Search Audit'!D:D,A34,'Search Audit'!E:E,"") -> 0 | D34: =B34-C34 -> 1 | E34: =IF(B34=0,0,C34/B34) -> 0 | F34: 487 pc suspect | G34: 1
A35: TOTAL | B35: =SUM(B4:B34) -> 1624 | C35: =SUM(C4:C34) -> 905 | D35: =SUM(D4:D34) -> 719 | E35: =IF(B35=0,0,C35/B35) -> 0.55726601
A38: Chart Data: Top 10 Network Counts by Volume
A39: Network Count | B39: Has Reason | C39: Blank Reason
A40: Net: 2 | B40: =D4 -> 87 | C40: =C4 -> 142
A41: Net: 3 | B41: =D5 -> 242 | C41: =C5 -> 280
A42: Net: 36 | B42: =D6 -> 15 | C42: =C6 -> 89
A43: Net: 15 | B43: =D7 -> 37 | C43: =C7 -> 44
A44: Net: 531 | B44: =D8 -> 67 | C44: =C8 -> 87
A45: Net: 1 | B45: =D9 -> 35 | C45: =C9 -> 50
A46: Net: 433 | B46: =D10 -> 37 | C46: =C10 -> 6
A47: Net: 532 | B47: =D11 -> 20 | C47: =C11 -> 21
A48: Net: 432 | B48: =D12 -> 36 | C48: =C12 -> 5
A49: Net: 35 | B49: =D13 -> 11 | C49: =C13 -> 37
A52: % Blank Rate by Network Count
A53: Network Count | B53: % Blank
A54: 2 | B54: =E4 -> 0.62008734
A55: 3 | B55: =E5 -> 0.53639847
A56: 36 | B56: =E6 -> 0.85576923
A57: 15 | B57: =E7 -> 0.54320988
A58: 531 | B58: =E8 -> 0.56493506
A59: 1 | B59: =E9 -> 0.58823529
A60: 433 | B60: =E10 -> 0.13953488
A61: 532 | B61: =E11 -> 0.51219512
A62: 432 | B62: =E12 -> 0.12195122
A63: 35 | B63: =E13 -> 0.77083333

Sheet Search Audit
A1: Search ID | B1: User ID | C1: Search Date (UTC/Zulu) | D1: Network Count | E1: Reason | F1: Search Date (Pacific) | G1: Date (Pacific) | H1: Day of Week | I1: Hour (Pacific)
A2: 0d467e68-708e-4b39-9eb7-83b2b7af3cc2 | B2: *** | C2: 46055.717 | D2: 15 | E2: 288 | F2: 46055.383 | G2: 46055 | H2: Monday | I2: 9
A3: 0699f1f0-50ac-441e-9b29-765e6469d80b | B3: *** | C3: 46055.766 | D3: 15 | E3: 288 | F3: 46055.433 | G3: 46055 | H3: Monday | I3: 10
A4: 35a6d6d0-05db-4caf-a9d1-8b7361638820 | B4: *** | C4: 46055.776 | D4: 2 | F4: 46055.443 | G4: 46055 | H4: Monday | I4: 10
A5: a1d98010-e5a7-41ac-b1ff-1b90e1c94e8e | B5: *** | C5: 46055.782 | D5: 4 | E5: STOLEN VEHICLE | F5: 46055.448 | G5: 46055 | H5: Monday | I5: 10
A6: 03af7616-75bc-4326-af92-ee81f6f30e27 | B6: *** | C6: 46055.792 | D6: 2 | E6: stolen veh | F6: 46055.458 | G6: 46055 | H6: Monday | I6: 11
A7: bb9a05ea-02fc-44e2-860a-c2dbf7cfe7e1 | B7: *** | C7: 46055.819 | D7: 15 | F7: 46055.486 | G7: 46055 | H7: Monday | I7: 11
A8: 7930b74f-fa09-4caf-90a7-3e7a7289db8f | B8: *** | C8: 46055.859 | D8: 2 | F8: 46055.526 | G8: 46055 | H8: Monday | I8: 12
A9: 05a06816-5fbd-45af-955a-631123af6549 | B9: *** | C9: 46055.864 | D9: 2 | F9: 46055.53 | G9: 46055 | H9: Monday | I9: 12
A10: 2a064e37-e2df-49cd-bf3a-d761776fdf4c | B10: *** | C10: 46055.869 | D10: 1 | F10: 46055.535 | G10: 46055 | H10: Monday | I10: 12
A11: 906d2967-5151-478b-a662-08ba5bcbc55b | B11: *** | C11: 46055.877 | D11: 2 | F11: 46055.544 | G11: 46055 | H11: Monday | I11: 13
A12: 576ba533-ddd3-46bb-a3dc-3e241ce4c0bf | B12: *** | C12: 46055.887 | D12: 15 | E12: 10851 | F12: 46055.554 | G12: 46055 | H12: Monday | I12: 13
A13: c329d679-e226-469d-bccd-1e61d57c9ba0 | B13: *** | C13: 46055.925 | D13: 15 | E13: 10851 | F13: 46055.592 | G13: 46055 | H13: Monday | I13: 14
A14: 88021183-a04b-4b7e-b244-97a189553aa9 | B14: *** | C14: 46055.938 | D14: 2 | F14: 46055.605 | G14: 46055 | H14: Monday | I14: 14
A15: 4b941c6b-2454-4484-8061-b2c37e5d66f4 | B15: *** | C15: 46055.985 | D15: 15 | E15: 10851 | F15: 46055.652 | G15: 46055 | H15: Monday | I15: 15
A16: 4be01773-0c22-4d3d-8e1b-4d5cc79a627c | B16: *** | C16: 46056.152 | D16: 2 | F16: 46055.819 | G16: 46055 | H16: Monday | I16: 19
A17: eae7fd71-08ff-445d-b7fb-72595f11a8c5 | B17: *** | C17: 46056.317 | D17: 2 | F17: 46055.984 | G17: 46055 | H17: Monday | I17: 23
A18: 761a53ad-9a16-4582-a1bb-353ea60fc6ac | B18: *** | C18: 46056.41 | D18: 433 | E18: Drug Investigation | F18: 46056.076 | G18: 46056 | H18: Tuesday | I18: 1
A19: 01bf7107-44ef-46c0-a4fa-17c279e84ce8 | B19: *** | C19: 46056.415 | D19: 2 | F19: 46056.081 | G19: 46056 | H19: Tuesday | I19: 1
A20: aa4b518d-aa1c-4481-9063-820e49274506 | B20: *** | C20: 46056.422 | D20: 433 | E20: suspect ID | F20: 46056.088 | G20: 46056 | H20: Tuesday | I20: 2
A21: 9836aabb-99c5-4186-a1a8-006936194e3f | B21: *** | C21: 46056.429 | D21: 433 | E21: Drug Investigation | F21: 46056.095 | G21: 46056 | H21: Tuesday | I21: 2
A22: 318cf320-dfa9-4192-969c-7eea817a39d6 | B22: *** | C22: 46056.46 | D22: 433 | E22: Drug Investigation | F22: 46056.126 | G22: 46056 | H22: Tuesday | I22: 3
A23: 94a74dfd-e059-4c27-a82b-22598a9bfcea | B23: *** | C23: 46056.497 | D23: 1 | E23: STOLEN VEHICLE | F23: 46056.164 | G23: 46056 | H23: Tuesday | I23: 3
A24: 9f0d5b1f-6308-4b46-9539-a055b19ccdc2 | B24: *** | C24: 46056.506 | D24: 2 | F24: 46056.173 | G24: 46056 | H24: Tuesday | I24: 4
A25: c344a0b3-eeca-4518-84ee-898bfbcadd1c | B25: *** | C25: 46056.577 | D25: 35 | F25: 46056.244 | G25: 46056 | H25: Tuesday | I25: 5
A26: 0d8b9b38-029f-46ea-95bf-55283c95db10 | B26: *** | C26: 46056.586 | D26: 433 | E26: Drug Investigation | F26: 46056.253 | G26: 46056 | H26: Tuesday | I26: 6
A27: 4148d926-e16e-40dd-8c64-996f20362cb4 | B27: *** | C27: 46056.614 | D27: 36 | E27: shooting suspect / stolen vehicle | F27: 46056.28 | G27: 46056 | H27: Tuesday | I27: 6
A28: 14a5ad81-f3ac-460a-af50-223c821a431d | B28: *** | C28: 46056.632 | D28: 433 | E28: Drug Investigation | F28: 46056.298 | G28: 46056 | H28: Tuesday | I28: 7
A29: b39315e8-17c3-43c5-9ba2-a73837adee27 | B29: *** | C29: 46056.643 | D29: 36 | E29: stolen vehicle | F29: 46056.31 | G29: 46056 | H29: Tuesday | I29: 7
A30: 84677b4b-7682-459d-a544-5790ed6c19bf | B30: *** | C30: 46056.669 | D30: 2 | E30: 288 | F30: 46056.336 | G30: 46056 | H30: Tuesday | I30: 8
A31: 47cc24e3-ff84-4f58-b96f-1e29090c3166 | B31: *** | C31: 46056.719 | D31: 15 | E31: 10851 | F31: 46056.385 | G31: 46056 | H31: Tuesday | I31: 9
A32: 80871e1d-4f8f-4ed6-b745-5e657e43595a | B32: *** | C32: 46056.723 | D32: 35 | F32: 46056.39 | G32: 46056 | H32: Tuesday | I32: 9
A33: d8a81c75-0754-496f-a1f6-12862436e50e | B33: *** | C33: 46056.757 | D33: 433 | E33: Drug investigations | F33: 46056.423 | G33: 46056 | H33: Tuesday | I33: 10
A34: 507eb95a-e75f-4405-89e8-da1a19180f01 | B34: *** | C34: 46056.759 | D34: 35 | F34: 46056.426 | G34: 46056 | H34: Tuesday | I34: 10
A35: 6929dcaa-b275-4821-8811-b983030ea7bf | B35: *** | C35: 46056.767 | D35: 15 | E35: 10851 | F35: 46056.434 | G35: 46056 | H35: Tuesday | I35: 10
A36: f20920d7-266d-459c-881b-f970824c6a34 | B36: *** | C36: 46056.802 | D36: 15 | E36: 10851 | F36: 46056.469 | G36: 46056 | H36: Tuesday | I36: 11
A37: 67be2a87-f768-4f73-8519-1619cb6560f5 | B37: *** | C37: 46056.81 | D37: 35 | F37: 46056.477 | G37: 46056 | H37: Tuesday | I37: 11
A38: d36d3e19-bc08-48e9-9e7a-5290d1ba3277 | B38: *** | C38: 46056.848 | D38: 15 | E38: 10851 | F38: 46056.515 | G38: 46056 | H38: Tuesday | I38: 12
A39: 17c01a91-a72f-43be-9a95-0d5969a6e94f | B39: *** | C39: 46056.884 | D39: 15 | E39: 10851 | F39: 46056.55 | G39: 46056 | H39: Tuesday | I39: 13
A40: dde6f2e4-b9ad-4ca6-a658-ab41f1933268 | B40: *** | C40: 46056.927 | D40: 15 | E40: 10851 | F40: 46056.594 | G40: 46056 | H40: Tuesday | I40: 14
...

Sheet flock_run_log
A1: Run Date/Time | B1: Rows Before | C1: Rows After | D1: New Rows | E1: New Rows Date Min | F1: New Rows Date Max | G1: Blank Reason # | H1: Blank Reason % | I1: Backdated Entries | J1: Backdated Detail | M1: Total Backdated Entries
A2: 46174.375 | B2: 2060 | C2: 2060 | D2: 0 | G2: 0 | H2: 0 | I2: 0 | M2: =SUM(I:I) -> 0
A3: 46173.583 | B3: 2046 | C3: 2060 | D3: 14 | E3: 46172 | F3: 46172 | G3: 10 | H3: 71.4 | I3: 0
A4: 46173.375 | B4: 2046 | C4: 2046 | D4: 0 | G4: 0 | H4: 0 | I4: 0
A5: 46172.621 | B5: 2036 | C5: 2046 | D5: 10 | E5: 46171 | F5: 46171 | G5: 8 | H5: 80 | I5: 0
A6: 46172.375 | B6: 2036 | C6: 2036 | D6: 0 | G6: 0 | H6: 0 | I6: 0
A7: 46171.583 | B7: 2024 | C7: 2036 | D7: 12 | E7: 46170 | F7: 46170 | G7: 9 | H7: 75 | I7: 0
A8: 46171.375 | B8: 2024 | C8: 2024 | D8: 0 | G8: 0 | H8: 0 | I8: 0
A9: 46170.583 | B9: 2018 | C9: 2024 | D9: 6 | E9: 46169 | F9: 46169 | G9: 4 | H9: 66.7 | I9: 0
A10: 46170.375 | B10: 2018 | C10: 2018 | D10: 0 | G10: 0 | H10: 0 | I10: 0
A11: 46169.583 | B11: 2010 | C11: 2018 | D11: 8 | E11: 46168 | F11: 46168 | G11: 6 | H11: 75 | I11: 0
A12: 46169.375 | B12: 2010 | C12: 2010 | D12: 0 | G12: 0 | H12: 0 | I12: 0
A13: 46168.814 | B13: 2006 | C13: 2010 | D13: 4 | E13: 46167 | F13: 46167 | G13: 3 | H13: 75 | I13: 0
A14: 46168.375 | B14: 2006 | C14: 2006 | D14: 0 | G14: 0 | H14: 0 | I14: 0
A15: 46167.712 | B15: 1995 | C15: 2006 | D15: 11 | E15: 46166 | F15: 46166 | G15: 8 | H15: 72.7 | I15: 0
A16: 46167.383 | B16: 1995 | C16: 1995 | D16: 0 | G16: 0 | H16: 0 | I16: 0
A17: 46166.583 | B17: 1990 | C17: 1995 | D17: 5 | E17: 46165 | F17: 46165 | G17: 4 | H17: 80 | I17: 0
A18: 46165.644 | B18: 1990 | C18: 1990 | D18: 0 | G18: 0 | H18: 0 | I18: 0
A19: 46165.634 | B19: 1978 | C19: 1990 | D19: 12 | E19: 46164 | F19: 46164 | G19: 8 | H19: 66.7 | I19: 0
A20: 46164.584 | B20: 477 | C20: 491 | D20: 14 | E20: 46163 | F20: 46163 | G20: 3 | H20: 21.4 | I20: 0
A21: 46164.375 | B21: 0 | C21: 477 | D21: 477 | E21: 46133 | F21: 46162 | G21: 289 | H21: 60.6 | I21: 0
